Workbook

Sheet Insights
A3: KEY STRATEGIC PHASES
A5: PHASE 1: EUROPEAN EXPANSION (2000-2007) | B5: Write-Up
A6: Period Performance | B6: 2000-2007
A7: Revenue Growth | B7: 3.6x (€2.6B to €9.4B)
A8: Key Initiatives | B8: IPO (2001), Multi-brand strategy (Pull&Bear, Massimo Dutti, Bershka)
A9: Store Growth | B9: 1,080 to 3,121 (+189%)
A10: EBITDA Margin | B10: 19.9% to 22.0% (stable)
A11: Critical Success Factor | B11: Vertical integration + JIT supply chain = competitive moat
A13: PHASE 2: GLOBAL DIVERSIFICATION (2008-2015)
A14: Period Performance | B14: 2008-2015
A15: Revenue Growth | B15: 2.0x (€10.4B to €20.9B)
A16: Key Initiatives | B16: Asia expansion, new formats (Oysho, Zara Home), E-commerce launch
A17: Store Growth | B17: 3,691 to 7,906 (+114%)
A18: EBITDA Margin | B18: 21.9% to 26.5% (22% improvement)
A19: Critical Success Factor | B19: Multi-channel strategy + emerging market penetration
A21: PHASE 3: DIGITAL TRANSFORMATION (2016-2019)
A22: Period Performance | B22: 2016-2019
A23: Revenue Growth | B23: 1.2x (€23.3B to €28.3B)
A24: Key Initiatives | B24: Omnichannel integration, online sales expansion (Zara.com, local markets)
A25: Store Growth | B25: 8,443 to 10,125 (+20%)
A26: EBITDA Margin | B26: 26.4% to 27.4% (plateau)
A27: Critical Success Factor | B27: Store productivity + digital experience = profitable growth
A29: PHASE 4: COVID RECOVERY & ACCELERATION (2020-2024)
A30: Period Performance | B30: 2020-2024
A31: Revenue Growth | B31: 1.8x (€20.9B to €38.2B)
A32: Key Initiatives | B32: Accelerated digital, store format innovation, Asian market consolidation
A33: Store Growth | B33: 10,596 to 12,631 (+19%)
A34: EBITDA Margin | B34: 27.0% to 28.5% (new peak)
A35: Critical Success Factor | B35: DTC (Direct-to-Consumer) + selective retail + operational excellence
A37: KEY PERFORMANCE DRIVERS
A39: 1. MARGIN EXPANSION | B39: 19.9% (2000) → 28.5% (2024) | +860 bps
B40: Drivers: Higher AUR, faster inventory turns, supply chain efficiency
A42: 2. CAPITAL EFFICIENCY | B42: ROE peaked 30.8% (2007), stabilized 18-25% (2008+)
B43: Improved shareholder returns through margin expansion and equity growth
A45: 3. OPERATIONAL SCALE | B45: €38.2B revenue on 12,631 stores = €3,026/store/year
B46: vs. competitors: H&M €269K/store, Gap €335K/store (Zara premium positioning)
A48: 4. TALENT LEVERAGE | B48: €114.4K sales per employee (2024)
B49: Highest in industry: H&M €122K, Gap €350K (Zara model: store staff productivity)
A51: COMPETITIVE ADVANTAGES
A53: ✓ Vertical Integration | B53: 40% in-house manufacturing (Spain/Portugal) vs. industry 5-10%
...

Sheet Financial Summary
A1: INDITEX GROUP - COMPREHENSIVE FINANCIAL MODEL (2000-2024)
A2: All figures in millions of euros unless otherwise noted
A4: Fiscal Year | B4: Net Sales (€M) | C4: EBITDA (€M) | D4: EBIT (€M) | E4: Net Income (€M) | F4: Shareholders Equity (€M) | G4: Total Assets (€M) | H4: Stores | I4: Employees
A5: 2000 | B5: 2614.7 | C5: 521.5 | D5: 379.9 | E5: 259.2 | F5: 1170.9 | G5: 2107.6 | H5: 1080 | I5: 24004
A6: 2001 | B6: 3249.8 | C6: 704.5 | D6: 517.5 | E6: 340.4 | F6: 1486.2 | G6: 2588.6 | H6: 1284 | I6: 26724
A7: 2002 | B7: 3974 | C7: 868.1 | D7: 659.5 | E7: 438.1 | F7: 1761.3 | G7: 3013.8 | H7: 1558 | I7: 32535
A8: 2003 | B8: 4598.9 | C8: 873.5 | D8: 627 | E8: 446.5 | F8: 2105.9 | G8: 3510.4 | H8: 1922 | I8: 39760
A9: 2004 | B9: 5670.4 | C9: 1239.7 | D9: 925.2 | E9: 628.1 | F9: 2502.7 | G9: 4209.2 | H9: 2244 | I9: 47046
A10: 2005 | B10: 6740.8 | C10: 1465 | D10: 1053 | E10: 810 | F10: 2961 | G10: 5054 | H10: 2632 | I10: 55708
A11: 2006 | B11: 8196.3 | C11: 1662 | D11: 1127 | E11: 860 | F11: 3341 | G11: 5847 | H11: 2872 | I11: 64680
A12: 2007 | B12: 9434.7 | C12: 2071 | D12: 1549 | E12: 1261 | F12: 4097 | G12: 7081 | H12: 3121 | I12: 79517
A13: 2008 | B13: 10407 | C13: 2282 | D13: 1701 | E13: 1262 | F13: 5005 | G13: 8475 | H13: 3691 | I13: 89112
A14: 2009 | B14: 11048 | C14: 2454 | D14: 1826 | E14: 1322 | F14: 5893 | G14: 10085 | H14: 4264 | I14: 92301
A15: 2010 | B15: 12527 | C15: 2966 | D15: 2290 | E15: 1741 | F15: 6916 | G15: 11814 | H15: 5044 | I15: 100138
A16: 2011 | B16: 13793 | C16: 3258 | D16: 2522 | E16: 1946 | F16: 7869 | G16: 13309 | H16: 5527 | I16: 109512
... A24: 2019 | B24: 28285 | C24: 7761 | D24: 6138 | E24: 5196 | F24: 23067 | G24: 31599 | H24: 10125 | I24: 236270
A25: 2020 | B25: 20916 | C25: 5654 | D25: 4452 | E25: 3288 | F25: 23883 | G25: 30813 | H25: 10596 | I25: 244387 | J25: COVID IMPACT
A26: 2021 | B26: 27718 | C26: 7833 | D26: 6188 | E26: 4640 | F26: 26883 | G26: 34555 | H26: 10899 | I26: 280308
A27: 2022 | B27: 32757 | C27: 9356 | D27: 7427 | E27: 5774 | F27: 30456 | G27: 38987 | H27: 11558 | I27: 299110
A28: 2023 | B28: 36163 | C28: 10221 | D28: 8195 | E28: 6371 | F28: 33956 | G28: 42381 | H28: 12117 | I28: 318379
A29: 2024 | B29: 38234 | C29: 10894 | D29: 8742 | E29: 6729 | F29: 37284 | G29: 46189 | H29: 12631 | I29: 334203

Sheet Key Metrics
A1: INDITEX KEY PERFORMANCE INDICATORS - STRATEGIC ANALYSIS (YEAR WISE)
A3: Year | B3: Revenue Growth % | C3: EBITDA Margin % | D3: Net Margin % | E3: ROE %
A4: 2000 | B4: NIL | C4: =('Financial Summary'!C5/'Financial Summary'!B5)*100 -> 19.944927 | D4: =('Financial Summary'!E5/'Financial Summary'!B5)*100 -> 9.9131832 | E4: =('Financial Summary'!E5/'Financial Summary'!F5)*100 -> 22.136818
A5: 2001 | B5: =('Financial Summary'!B6-'Financial Summary'!B5)/'Financial Summary'!B5*100 -> 24.289593 | C5: =('Financial Summary'!C6/'Financial Summary'!B6)*100 -> 21.678257 | D5: =('Financial Summary'!E6/'Financial Summary'!B6)*100 -> 10.474491 | E5: =('Financial Summary'!E6/'Financial Summary'!F6)*100 -> 22.904051
A6: 2002 | B6: =('Financial Summary'!B7-'Financial Summary'!B6)/'Financial Summary'!B6*100 -> 22.284448 | C6: =('Financial Summary'!C7/'Financial Summary'!B7)*100 -> 21.844489 | D6: =('Financial Summary'!E7/'Financial Summary'!B7)*100 -> 11.024157 | E6: =('Financial Summary'!E7/'Financial Summary'!F7)*100 -> 24.873673
A7: 2003 | B7: =('Financial Summary'!B8-'Financial Summary'!B7)/'Financial Summary'!B7*100 -> 15.724711 | C7: =('Financial Summary'!C8/'Financial Summary'!B8)*100 -> 18.993672 | D7: =('Financial Summary'!E8/'Financial Summary'!B8)*100 -> 9.7088434 | E7: =('Financial Summary'!E8/'Financial Summary'!F8)*100 -> 21.202336
A8: 2004 | B8: =('Financial Summary'!B9-'Financial Summary'!B8)/'Financial Summary'!B8*100 -> 23.29905 | C8: =('Financial Summary'!C9/'Financial Summary'!B9)*100 -> 21.862655 | D8: =('Financial Summary'!E9/'Financial Summary'!B9)*100 -> 11.07682 | E8: =('Financial Summary'!E9/'Financial Summary'!F9)*100 -> 25.096895
A9: 2005 | B9: =('Financial Summary'!B10-'Financial Summary'!B9)/'Financial Summary'!B9*100 -> 18.876975 | C9: =('Financial Summary'!C10/'Financial Summary'!B10)*100 -> 21.733325 | D9: =('Financial Summary'!E10/'Financial Summary'!B10)*100 -> 12.016378 | E9: =('Financial Summary'!E10/'Financial Summary'!F10)*100 -> 27.355623
A10: 2006 | B10: =('Financial Summary'!B11-'Financial Summary'!B10)/'Financial Summary'!B10*100 -> 21.592393 | C10: =('Financial Summary'!C11/'Financial Summary'!B11)*100 -> 20.277442 | D10: =('Financial Summary'!E11/'Financial Summary'!B11)*100 -> 10.492539 | E10: =('Financial Summary'!E11/'Financial Summary'!F11)*100 -> 25.740796
A11: 2007 | B11: =('Financial Summary'!B12-'Financial Summary'!B11)/'Financial Summary'!B11*100 -> 15.109257 | C11: =('Financial Summary'!C12/'Financial Summary'!B12)*100 -> 21.950883 | D11: =('Financial Summary'!E12/'Financial Summary'!B12)*100 -> 13.365555 | E11: =('Financial Summary'!E12/'Financial Summary'!F12)*100 -> 30.778619
A12: 2008 | B12: =('Financial Summary'!B13-'Financial Summary'!B12)/'Financial Summary'!B12*100 -> 10.305574 | C12: =('Financial Summary'!C13/'Financial Summary'!B13)*100 -> 21.927549 | D12: =('Financial Summary'!E13/'Financial Summary'!B13)*100 -> 12.126453 | E12: =('Financial Summary'!E13/'Financial Summary'!F13)*100 -> 25.214785
A13: 2009 | B13: =('Financial Summary'!B14-'Financial Summary'!B13)/'Financial Summary'!B13*100 -> 6.1593158 | C13: =('Financial Summary'!C14/'Financial Summary'!B14)*100 -> 22.212165 | D13: =('Financial Summary'!E14/'Financial Summary'!B14)*100 -> 11.965967 | E13: =('Financial Summary'!E14/'Financial Summary'!F14)*100 -> 22.433396
A14: 2010 | B14: =('Financial Summary'!B15-'Financial Summary'!B14)/'Financial Summary'!B14*100 -> 13.387038 | C14: =('Financial Summary'!C15/'Financial Summary'!B15)*100 -> 23.676858 | D14: =('Financial Summary'!E15/'Financial Summary'!B15)*100 -> 13.89798 | E14: =('Financial Summary'!E15/'Financial Summary'!F15)*100 -> 25.173511
A15: 2011 | B15: =('Financial Summary'!B16-'Financial Summary'!B15)/'Financial Summary'!B15*100 -> 10.106171 | C15: =('Financial Summary'!C16/'Financial Summary'!B16)*100 -> 23.620677 | D15: =('Financial Summary'!E16/'Financial Summary'!B16)*100 -> 14.108606 | E15: =('Financial Summary'!E16/'Financial Summary'!F16)*100 -> 24.729953
A16: 2012 | B16: =('Financial Summary'!B17-'Financial Summary'!B16)/'Financial Summary'!B16*100 -> 6.9745523 | C16: =('Financial Summary'!C17/'Financial Summary'!B17)*100 -> 24.181633 | D16: =('Financial Summary'!E17/'Financial Summary'!B17)*100 -> 14.618773 | E16: =('Financial Summary'!E17/'Financial Summary'!F17)*100 -> 24.01737
... A28: 2024 | B28: =('Financial Summary'!B29-'Financial Summary'!B28)/'Financial Summary'!B28*100 -> 5.7268479 | C28: =('Financial Summary'!C29/'Financial Summary'!B29)*100 -> 28.492964 | D28: =('Financial Summary'!E29/'Financial Summary'!B29)*100 -> 17.599519 | E28: =('Financial Summary'!E29/'Financial Summary'!F29)*100 -> 18.047956

Sheet Operational Efficiency
A1: OPERATIONAL & CAPITAL EFFICIENCY METRICS
A3: Year | B3: Sales per Store (€M) | C3: Sales per Employee (€K) | D3: ROIC % | E3: Asset Turnover | F3: Operational Efficiency
A4: 2000 | B4: ='Financial Summary'!B5/'Financial Summary'!H5 -> 2.4210185 | C4: =('Financial Summary'!B5*1000)/'Financial Summary'!I5 -> 108.92768 | D4: =('Financial Summary'!D5*(1-0.25))/'Financial Summary'!G5 -> 0.13518931 | E4: ='Financial Summary'!B5/'Financial Summary'!G5 -> 1.2406054 | F4: ='Financial Summary'!G5/'Financial Summary'!F5 -> 1.7999829
A5: 2001 | B5: ='Financial Summary'!B6/'Financial Summary'!H6 -> 2.5309969 | C5: =('Financial Summary'!B6*1000)/'Financial Summary'!I6 -> 121.60605 | D5: =('Financial Summary'!D6*(1-0.25))/'Financial Summary'!G6 -> 0.14993626 | E5: ='Financial Summary'!B6/'Financial Summary'!G6 -> 1.2554276 | F5: ='Financial Summary'!G6/'Financial Summary'!F6 -> 1.7417575
A6: 2002 | B6: ='Financial Summary'!B7/'Financial Summary'!H7 -> 2.550706 | C6: =('Financial Summary'!B7*1000)/'Financial Summary'!I7 -> 122.14538 | D6: =('Financial Summary'!D7*(1-0.25))/'Financial Summary'!G7 -> 0.16412005 | E6: ='Financial Summary'!B7/'Financial Summary'!G7 -> 1.3186011 | F6: ='Financial Summary'!G7/'Financial Summary'!F7 -> 1.7111225
A7: 2003 | B7: ='Financial Summary'!B8/'Financial Summary'!H8 -> 2.392768 | C7: =('Financial Summary'!B8*1000)/'Financial Summary'!I8 -> 115.6665 | D7: =('Financial Summary'!D8*(1-0.25))/'Financial Summary'!G8 -> 0.13395909 | E7: ='Financial Summary'!B8/'Financial Summary'!G8 -> 1.3100786 | F7: ='Financial Summary'!G8/'Financial Summary'!F8 -> 1.6669358
A8: 2004 | B8: ='Financial Summary'!B9/'Financial Summary'!H9 -> 2.5269162 | C8: =('Financial Summary'!B9*1000)/'Financial Summary'!I9 -> 120.52884 | D8: =('Financial Summary'!D9*(1-0.25))/'Financial Summary'!G9 -> 0.16485318 | E8: ='Financial Summary'!B9/'Financial Summary'!G9 -> 1.3471444 | F8: ='Financial Summary'!G9/'Financial Summary'!F9 -> 1.6818636
A9: 2005 | B9: ='Financial Summary'!B10/'Financial Summary'!H10 -> 2.5610942 | C9: =('Financial Summary'!B10*1000)/'Financial Summary'!I10 -> 121.00237 | D9: =('Financial Summary'!D10*(1-0.25))/'Financial Summary'!G10 -> 0.15626237 | E9: ='Financial Summary'!B10/'Financial Summary'!G10 -> 1.3337554 | F9: ='Financial Summary'!G10/'Financial Summary'!F10 -> 1.7068558
A10: 2006 | B10: ='Financial Summary'!B11/'Financial Summary'!H11 -> 2.8538649 | C10: =('Financial Summary'!B11*1000)/'Financial Summary'!I11 -> 126.72078 | D10: =('Financial Summary'!D11*(1-0.25))/'Financial Summary'!G11 -> 0.14456131 | E10: ='Financial Summary'!B11/'Financial Summary'!G11 -> 1.4017958 | F10: ='Financial Summary'!G11/'Financial Summary'!F11 -> 1.7500748
A11: 2007 | B11: ='Financial Summary'!B12/'Financial Summary'!H12 -> 3.0229734 | C11: =('Financial Summary'!B12*1000)/'Financial Summary'!I12 -> 118.6501 | D11: =('Financial Summary'!D12*(1-0.25))/'Financial Summary'!G12 -> 0.16406581 | E11: ='Financial Summary'!B12/'Financial Summary'!G12 -> 1.3323966 | F11: ='Financial Summary'!G12/'Financial Summary'!F12 -> 1.7283378
A12: 2008 | B12: ='Financial Summary'!B13/'Financial Summary'!H13 -> 2.8195611 | C12: =('Financial Summary'!B13*1000)/'Financial Summary'!I13 -> 116.78562 | D12: =('Financial Summary'!D13*(1-0.25))/'Financial Summary'!G13 -> 0.15053097 | E12: ='Financial Summary'!B13/'Financial Summary'!G13 -> 1.2279646 | F12: ='Financial Summary'!G13/'Financial Summary'!F13 -> 1.6933067
A13: 2009 | B13: ='Financial Summary'!B14/'Financial Summary'!H14 -> 2.5909944 | C13: =('Financial Summary'!B14*1000)/'Financial Summary'!I14 -> 119.69534 | D13: =('Financial Summary'!D14*(1-0.25))/'Financial Summary'!G14 -> 0.13579574 | E13: ='Financial Summary'!B14/'Financial Summary'!G14 -> 1.0954883 | F13: ='Financial Summary'!G14/'Financial Summary'!F14 -> 1.7113525
A14: 2010 | B14: ='Financial Summary'!B15/'Financial Summary'!H15 -> 2.4835448 | C14: =('Financial Summary'!B15*1000)/'Financial Summary'!I15 -> 125.09737 | D14: =('Financial Summary'!D15*(1-0.25))/'Financial Summary'!G15 -> 0.14537836 | E14: ='Financial Summary'!B15/'Financial Summary'!G15 -> 1.0603521 | F14: ='Financial Summary'!G15/'Financial Summary'!F15 -> 1.7082128
A15: 2011 | B15: ='Financial Summary'!B16/'Financial Summary'!H16 -> 2.4955672 | C15: =('Financial Summary'!B16*1000)/'Financial Summary'!I16 -> 125.94967 | D15: =('Financial Summary'!D16*(1-0.25))/'Financial Summary'!G16 -> 0.14212187 | E15: ='Financial Summary'!B16/'Financial Summary'!G16 -> 1.0363664 | F15: ='Financial Summary'!G16/'Financial Summary'!F16 -> 1.6913204
... A28: 2024 | B28: ='Financial Summary'!B29/'Financial Summary'!H29 -> 3.0269971 | C28: =('Financial Summary'!B29*1000)/'Financial Summary'!I29 -> 114.40352 | D28: =('Financial Summary'!D29*(1-0.25))/'Financial Summary'!G29 -> 0.14194938 | E28: ='Financial Summary'!B29/'Financial Summary'!G29 -> 0.82777285 | F28: ='Financial Summary'!G29/'Financial Summary'!F29 -> 1.2388424

Sheet CAGR (3-Year Rolling)
A1: Rolling 3-Year Period End | B1: 3-Year Sales CAGR % | C1: 3-Year Net Income CAGR % | D1: Strategic Phase | E1: Column1
A2: 2003 | B2: =('Financial Summary'!B8/'Financial Summary'!B5)^(1/3)-1 -> 0.20710218 | C2: =('Financial Summary'!E8/'Financial Summary'!E5)^(1/3)-1 -> 0.19875056 | D2: The Golden Era | E2: Income CAGR > Sales CAGR. Proven concept, massive expansion.
A3: 2004 | B3: =('Financial Summary'!B9/'Financial Summary'!B6)^(1/3)-1 -> 0.2038869 | C3: =('Financial Summary'!E9/'Financial Summary'!E6)^(1/3)-1 -> 0.22653444 | D3: The Golden Era | E3: Income CAGR > Sales CAGR. Proven concept, massive expansion.
A4: 2005 | B4: =('Financial Summary'!B10/'Financial Summary'!B7)^(1/3)-1 -> 0.19259923 | C4: =('Financial Summary'!E10/'Financial Summary'!E7)^(1/3)-1 -> 0.22735611 | D4: The Golden Era | E4: Income CAGR > Sales CAGR. Proven concept, massive expansion.
A5: 2006 | B5: =('Financial Summary'!B11/'Financial Summary'!B8)^(1/3)-1 -> 0.21242428 | C5: =('Financial Summary'!E11/'Financial Summary'!E8)^(1/3)-1 -> 0.24420611 | D5: The Golden Era | E5: Income CAGR > Sales CAGR. Proven concept, massive expansion.
A6: 2007 | B6: =('Financial Summary'!B12/'Financial Summary'!B9)^(1/3)-1 -> 0.18496303 | C6: =('Financial Summary'!E12/'Financial Summary'!E9)^(1/3)-1 -> 0.26152375 | D6: The Golden Era | E6: Income CAGR > Sales CAGR. Proven concept, massive expansion.
A7: 2008 | B7: =('Financial Summary'!B13/'Financial Summary'!B10)^(1/3)-1 -> 0.15576988 | C7: =('Financial Summary'!E13/'Financial Summary'!E10)^(1/3)-1 -> 0.15928828 | D7: The Resilience | E7: Sales dropped to ~10%, but Profit held up. Survived Financial Crisis better than peers.
A8: 2009 | B8: =('Financial Summary'!B14/'Financial Summary'!B11)^(1/3)-1 -> 0.10464299 | C8: =('Financial Summary'!E14/'Financial Summary'!E11)^(1/3)-1 -> 0.15410237 | D8: The Resilience | E8: Sales dropped to ~10%, but Profit held up. Survived Financial Crisis better than peers.
A9: 2010 | B9: =('Financial Summary'!B15/'Financial Summary'!B12)^(1/3)-1 -> 0.099106208 | C9: =('Financial Summary'!E15/'Financial Summary'!E12)^(1/3)-1 -> 0.11351113 | D9: The Resilience | E9: Sales dropped to ~10%, but Profit held up. Survived Financial Crisis better than peers.
A10: 2011 | B10: =('Financial Summary'!B16/'Financial Summary'!B13)^(1/3)-1 -> 0.09844351 | C10: =('Financial Summary'!E16/'Financial Summary'!E13)^(1/3)-1 -> 0.15529926 | D10: The Resilience | E10: Sales dropped to ~10%, but Profit held up. Survived Financial Crisis better than peers.
A11: 2012 | B11: =('Financial Summary'!B17/'Financial Summary'!B14)^(1/3)-1 -> 0.10124813 | C11: =('Financial Summary'!E17/'Financial Summary'!E14)^(1/3)-1 -> 0.17726138 | D11: The Resilience | E11: Sales dropped to ~10%, but Profit held up. Survived Financial Crisis better than peers.
A12: 2013 | B12: =('Financial Summary'!B18/'Financial Summary'!B15)^(1/3)-1 -> 0.076465827 | C12: =('Financial Summary'!E18/'Financial Summary'!E15)^(1/3)-1 -> 0.11262839 | D12: The Digital Squeeze | E12: Profit growth lagged Sales. (The "Death Valley"). Investing heavily in Online + Closing small stores.
A13: 2014 | B13: =('Financial Summary'!B19/'Financial Summary'!B16)^(1/3)-1 -> 0.079684819 | C13: =('Financial Summary'!E19/'Financial Summary'!E16)^(1/3)-1 -> 0.13455898 | D13: The Digital Squeeze | E13: Profit growth lagged Sales. (The "Death Valley"). Investing heavily in Online + Closing small stores.
... A23: 2024 | B23: =('Financial Summary'!B29/'Financial Summary'!B26)^(1/3)-1 -> 0.11317287 | C23: =('Financial Summary'!E29/'Financial Summary'!E26)^(1/3)-1 -> 0.13190727 | D23: The Efficiency Beast | E23: Profit exploding (20%+). The investments paid off. Digital + Physical integration is printing cash.

Sheet Valuation
A1: INDITEX VALUATION DASHBOARD (FEB 2026)
A2: Metric | B2: Value
A3: Current Stock Price (Feb 2026) | B3: 55.5
A4: Trailing 12M EPS (€) | B4: 1.98
A5: P/E Ratio | B5: =B3/B4 -> 28.030303
A6: Growth Rate (Net Income 3Y CAGR) | B6: 13.2
A7: PEG Ratio | B7: =B5/B6 -> 2.1235078
A8: Valuation Verdict | B8: =IF(B7>2, "Overvalued", IF(B7<1, "Undervalued", "Fair Value")) -> Overvalued
A11: PRICE SENSITIVITY ANALYSIS (Based on 13.2% Growth)
A13: Scenario | B13: Target PEG | C13: Implied P/E | D13: Implied Stock Price (€)
A14: Undervalued (Value Buy) | B14: 1 | C14: =B14*$B$6 -> 13.2 | D14: =C14*$B$4 -> 26.136
A15: Fair Value (GARP) | B15: 1.5 | C15: =B15*$B$6 -> 19.8 | D15: =C15*$B$4 -> 39.204
A16: Growth Premium | B16: 2 | C16: =B16*$B$6 -> 26.4 | D16: =C16*$B$4 -> 52.272
A17: Current Market Pricing | B17: 2.12 | C17: =B17*$B$6 -> 27.984 | D17: =C17*$B$4 -> 55.40832
